<?xml version="1.0" ?>
<!-- =================================================================================== -->
<!-- |    This document was autogenerated by xacro from ./urdf/urdf_assembly_2.xacro   | -->
<!-- |    EDITING THIS FILE BY HAND IS NOT RECOMMENDED                                 | -->
<!-- =================================================================================== -->
<robot name="urdf_assembly_2">
  <material name="silver">
    <color rgba="0.700 0.700 0.700 1.000"/>
  </material>

  <link name="base_link">
    <inertial>
      <origin rpy="0 0 0" xyz="-0.0342362509848714 -0.0039161533991028665 -0.02839103797627507"/>
      <mass value="2.2003666449760275"/>
      <inertia ixx="0.015633" ixy="0.000363" ixz="0.001133" iyy="0.02691" iyz="0.000114" izz="0.040737"/>
    </inertial>
    <visual>
      <origin rpy="0 0 0" xyz="0 0 0"/>
      <geometry>
        <mesh filename="meshes/base_link.stl" scale="0.001 0.001 0.001"/>
      </geometry>
      <material name="silver"/>
    </visual>
    <collision>
      <origin rpy="0 0 0" xyz="0 0 0"/>
      <geometry>
        <mesh filename="meshes/base_link.stl" scale="0.001 0.001 0.001"/>
      </geometry>
    </collision>
  </link>
  <link name="link_1_1">
    <inertial>
      <origin rpy="0 0 0" xyz="-0.03473888377200399 0.0006648494543459067 0.07800139222078076"/>
      <mass value="15.038966546923882"/>
      <inertia ixx="0.05038" ixy="0.001073" ixz="0.005378" iyy="0.107214" iyz="-0.000117" izz="0.097015"/>
    </inertial>
    <visual>
      <origin rpy="0 0 0" xyz="0.002859 0.005179 0.00232"/>
      <geometry>
        <mesh filename="meshes/link_1_1.stl" scale="0.001 0.001 0.001"/>
      </geometry>
      <material name="silver"/>
    </visual>
    <collision>
      <origin rpy="0 0 0" xyz="0.002859 0.005179 0.00232"/>
      <geometry>
        <mesh filename="meshes/link_1_1.stl" scale="0.001 0.001 0.001"/>
      </geometry>
    </collision>
  </link>
  <link name="link_2_1">
    <inertial>
      <origin rpy="0 0 0" xyz="2.601990558093962e-05 -0.0008884927878232626 0.13687536190298447"/>
      <mass value="12.313102715674546"/>
      <inertia ixx="0.196874" ixy="-0.0" ixz="-5.2e-05" iyy="0.179594" iyz="-0.000195" izz="0.037663"/>
    </inertial>
    <visual>
      <origin rpy="0 0 0" xyz="0.002859 0.005179 -0.13368"/>
      <geometry>
        <mesh filename="meshes/link_2_1.stl" scale="0.001 0.001 0.001"/>
      </geometry>
      <material name="silver"/>
    </visual>
    <collision>
      <origin rpy="0 0 0" xyz="0.002859 0.005179 -0.13368"/>
      <geometry>
        <mesh filename="meshes/link_2_1.stl" scale="0.001 0.001 0.001"/>
      </geometry>
    </collision>
  </link>
  <link name="link_3_1">
    <inertial>
      <origin rpy="0 0 0" xyz="-0.01628301021334254 0.00016122524353749754 0.07497927196563697"/>
      <mass value="9.121346283290388"/>
      <inertia ixx="0.062586" ixy="-2.5e-05" ixz="0.007821" iyy="0.063998" iyz="0.000107" izz="0.038355"/>
    </inertial>
    <visual>
      <origin rpy="0 0 0" xyz="0.002698 0.005179 -0.432846"/>
      <geometry>
        <mesh filename="meshes/link_3_1.stl" scale="0.001 0.001 0.001"/>
      </geometry>
      <material name="silver"/>
    </visual>
    <collision>
      <origin rpy="0 0 0" xyz="0.002698 0.005179 -0.432846"/>
      <geometry>
        <mesh filename="meshes/link_3_1.stl" scale="0.001 0.001 0.001"/>
      </geometry>
    </collision>
  </link>
  <link name="link_4_1">
    <inertial>
      <origin rpy="0 0 0" xyz="0.06639448325545491 0.0006371339116822963 -1.5979938389532045e-05"/>
      <mass value="6.333915973707803"/>
      <inertia ixx="0.010346" ixy="-0.000175" ixz="1e-05" iyy="0.102497" iyz="5e-06" izz="0.108204"/>
    </inertial>
    <visual>
      <origin rpy="0 0 0" xyz="-0.057302 0.005179 -0.530733"/>
      <geometry>
        <mesh filename="meshes/link_4_1.stl" scale="0.001 0.001 0.001"/>
      </geometry>
      <material name="silver"/>
    </visual>
    <collision>
      <origin rpy="0 0 0" xyz="-0.057302 0.005179 -0.530733"/>
      <geometry>
        <mesh filename="meshes/link_4_1.stl" scale="0.001 0.001 0.001"/>
      </geometry>
    </collision>
  </link>
  <link name="link_5_1">
    <inertial>
      <origin rpy="0 0 0" xyz="0.05519576996196435 8.727471742780296e-08 0.020926890757093308"/>
      <mass value="3.395965317211299"/>
      <inertia ixx="0.007088" ixy="0.0" ixz="-0.002334" iyy="0.011532" iyz="-0.0" izz="0.008294"/>
    </inertial>
    <visual>
      <origin rpy="0 0 0" xyz="-0.274302 0.005096 -0.530663"/>
      <geometry>
        <mesh filename="meshes/link_5_1.stl" scale="0.001 0.001 0.001"/>
      </geometry>
      <material name="silver"/>
    </visual>
    <collision>
      <origin rpy="0 0 0" xyz="-0.274302 0.005096 -0.530663"/>
      <geometry>
        <mesh filename="meshes/link_5_1.stl" scale="0.001 0.001 0.001"/>
      </geometry>
    </collision>
  </link>
  <link name="link_6_1">
    <inertial>
      <origin rpy="0 0 0" xyz="-0.003933804309610656 1.3555235880025746e-07 -2.1343392964112695e-07"/>
      <mass value="0.19190462961219334"/>
      <inertia ixx="9.1e-05" ixy="0.0" ixz="-0.0" iyy="5.2e-05" iyz="-0.0" izz="5.2e-05"/>
    </inertial>
    <visual>
      <origin rpy="0 0 0" xyz="-0.391802 0.005096 -0.530663"/>
      <geometry>
        <mesh filename="meshes/link_6_1.stl" scale="0.001 0.001 0.001"/>
      </geometry>
      <material name="silver"/>
    </visual>
    <collision>
      <origin rpy="0 0 0" xyz="-0.391802 0.005096 -0.530663"/>
      <geometry>
        <mesh filename="meshes/link_6_1.stl" scale="0.001 0.001 0.001"/>
      </geometry>
    </collision>
  </link>
  <link name="link_7_1">
    <inertial>
      <origin rpy="0 0 0" xyz="0.05912945593498742 9.350275258987462e-07 -0.0011405877959500543"/>
      <mass value="2.520414679263601"/>
      <inertia ixx="0.001981" ixy="1e-06" ixz="-9.8e-05" iyy="0.006996" iyz="0.0" izz="0.007915"/>
    </inertial>
    <visual>
      <origin rpy="0 0 0" xyz="-0.606632  0.005096 -0.530663"/>
      <geometry>
        <mesh filename="meshes/link_7_1.stl" scale="0.001 0.001 0.001"/>
      </geometry>
      <material name="silver"/>
    </visual>
    <collision>
      <origin rpy="0 0 0" xyz="-0.396802 0.005096 -0.530663"/>
      <geometry>
        <mesh filename="meshes/link_7_1.stl" scale="0.001 0.001 0.001"/>
      </geometry>
    </collision>
  </link>
  <joint name="joint_1" type="revolute">
    <origin rpy="0 0 0" xyz="-0.002859 -0.005179 -0.00232"/>
    <parent link="base_link"/>
    <child link="link_1_1"/>
    <axis xyz="0.0 0.0 1.0"/>
    <limit effort="100" lower="-2.094395" upper="2.094395" velocity="100"/>
  </joint>
  <joint name="joint_2" type="revolute">
    <origin rpy="0 0 0" xyz="0.0 0.0 0.136"/>
    <parent link="link_1_1"/>
    <child link="link_2_1"/>
    <axis xyz="-0.0 -1.0 -0.0"/>
    <limit effort="100" lower="-1.570796" upper="0.947714" velocity="100"/>
  </joint>
  <joint name="joint_3" type="revolute">
    <origin rpy="0 0 0" xyz="0.000161 0.0 0.299166"/>
    <parent link="link_2_1"/>
    <child link="link_3_1"/>
    <axis xyz="-0.0 -1.0 0.0"/>
    <limit effort="100" lower="-1.570796" upper="1.570796" velocity="100"/>
  </joint>
  <joint name="joint_4" type="revolute">
    <origin rpy="0 0 0" xyz="0.06 0.0 0.097887"/>
    <parent link="link_3_1"/>
    <child link="link_4_1"/>
    <axis xyz="1.0 -0.0 0.0"/>
    <limit effort="100" lower="-3.141593" upper="3.141593" velocity="100"/>
  </joint>
  <joint name="joint_5" type="revolute">
    <origin rpy="0 0 0" xyz="0.217 8.3e-05 -7e-05"/>
    <parent link="link_4_1"/>
    <child link="link_5_1"/>
    <axis xyz="-0.0 -1.0 0.0"/>
    <limit effort="100" lower="-2.356194" upper="2.007129" velocity="100"/>
  </joint>
  <joint name="joint_6" type="revolute">
    <origin rpy="0 0 0" xyz="0.1175 0.0 0.0"/>
    <parent link="link_5_1"/>
    <child link="link_6_1"/>
    <axis xyz="1.0 0.0 0.0"/>
    <limit effort="100" lower="-3.141593" upper="3.141593" velocity="100"/>
  </joint>
  <joint name="joint_7" type="revolute">
    <origin rpy="0 0 0" xyz="0.20982 0.0 0.0"/>
    <parent link="link_6_1"/>
    <axis xyz="1.0 0.0 0.0"/>
    <child link="link_7_1"/>
    <limit effort="100" lower="-3.141593" upper="3.141593" velocity="100"/>
  </joint>
</robot>

