<?xml version="1.0" ?>
<!-- =================================================================================== -->
<!-- |    This document was autogenerated by xacro from /home/maven/maven_ws/src/robot_arm_description/urdf/urdf_assembly.xacro | -->
<!-- |    EDITING THIS FILE BY HAND IS NOT RECOMMENDED                                 | -->
<!-- =================================================================================== -->
<robot name="robot_arm">
    
    <link name="base_link">
  <inertial>
    <origin xyz="0 0 0" rpy="0 0 0"/>
    <mass value="2.200366644976027"/>
    <inertia ixx="0.02691" iyy="0.015633" izz="0.040737" ixy="-0.000363" iyz="0.001133" ixz="-0.000114"/>
  </inertial>
  <visual>
    <origin xyz="0 0 0" rpy="0 0 0"/>
    <geometry>
      <mesh filename="package://robot_arm_description/meshes/base_link.stl" scale="0.001 0.001 0.001"/>
    </geometry>
    <material name="silver"/>
  </visual>
  <collision>
    <origin xyz="0 0 0" rpy="0 0 0"/>
    <geometry>
      <mesh filename="package://robot_arm_description/meshes/base_link.stl" scale="0.001 0.001 0.001"/>
    </geometry>
  </collision>
</link>

<link name="link_1_1">
  <inertial>
    <origin xyz="0 0 0.024001498636141927" rpy="0 0 0"/>
    <mass value="2.030739431813925"/>
    <inertia ixx="0.014477" iyy="0.006803" izz="0.0131" ixy="-0.000145" iyz="0.000726" ixz="1.6e-05"/>
  </inertial>
  <visual>
    <origin xyz="0 0 -0.117341" rpy="0 0 0"/>
    <geometry>
      <mesh filename="package://robot_arm_description/meshes/link_1_1.stl" scale="0.001 0.001 0.001"/>
    </geometry>
    <material name="silver"/>
  </visual>
  <collision>
    <origin xyz="0 0 -0.117341" rpy="0 0 0"/>
    <geometry>
      <mesh filename="package://robot_arm_description/meshes/link_1_1.stl" scale="0.001 0.001 0.001"/>
    </geometry>
  </collision>
</link>

<link name="link_2_1">
  <inertial>
    <origin xyz="0 0 0.13687546860146899" rpy="0 0 0"/>
    <mass value="1.6626610036452254"/>
    <inertia ixx="0.024251" iyy="0.026584" izz="0.005086" ixy="0.0" iyz="7e-06" ixz="-2.6e-05"/>
  </inertial>
  <visual>
    <origin xyz="0 0.002 -0.199341" rpy="0 0 0"/>
    <geometry>
      <mesh filename="package://robot_arm_description/meshes/link_2_1.stl" scale="0.001 0.001 0.001"/>
    </geometry>
    <material name="silver"/>
  </visual>
  <collision>
    <origin xyz="0 0 -0.199341" rpy="0 0 0"/>
    <geometry>
      <mesh filename="package://robot_arm_description/meshes/link_2_1.stl" scale="0.001 0.001 0.001"/>
    </geometry>
  </collision>
</link>

<link name="link_3_1">
  <inertial>
    <origin xyz="0 -0.016283006892585307 0.07497937866412202" rpy="0 0 0"/>
    <mass value="9.121346283290384"/>
    <inertia ixx="0.063998" iyy="0.062586" izz="0.038355" ixy="2.5e-05" iyz="0.007821" ixz="-0.000107"/>
  </inertial>
  <visual>
    <origin xyz="0 0.002793 -0.498507" rpy="0 0 0"/>
    <geometry>
      <mesh filename="package://robot_arm_description/meshes/link_3_1.stl" scale="0.001 0.001 0.001"/>
    </geometry>
    <material name="silver"/>
  </visual>
  <collision>
    <origin xyz="0 0.002793 -0.498507" rpy="0 0 0"/>
    <geometry>
      <mesh filename="package://robot_arm_description/meshes/link_3_1.stl" scale="0.001 0.001 0.001"/>
    </geometry>
  </collision>
</link>

<link name="link_4_1">
  <inertial>
    <origin xyz="0.005513953778460314 0.2625680653929481 4.057984306360396e-06" rpy="0 0 0"/>
    <mass value="7.5787166188185005"/>
    <inertia ixx="0.126085" iyy="0.027107" izz="0.147683" ixy="-0.000913" iyz="-1e-06" ixz="-2e-06"/>
  </inertial>
  <visual>
    <origin xyz="0.0 0.0 -0.596394" rpy="0 0 0"/>
    <geometry>
      <mesh filename="package://robot_arm_description/meshes/link_4_1.stl" scale="0.001 0.001 0.001"/>
    </geometry>
    <material name="silver"/>
  </visual>
  <collision>
    <origin xyz="0.002859 0.0 -0.596394" rpy="0 0 0"/>
    <geometry>
      <mesh filename="package://robot_arm_description/meshes/link_4_1.stl" scale="0.001 0.001 0.001"/>
    </geometry>
  </collision>
</link>

<link name="link_5_1">
  <inertial>
    <origin xyz="-0.07848672877351807 -0.01878037329851351 1.0025048180262175e-05" rpy="0 0 0"/>
    <mass value="3.0872435381050845"/>
    <inertia ixx="0.004619" iyy="0.008205" izz="0.009933" ixy="-0.001102" iyz="2e-06" ixz="0.0"/>
  </inertial>
  <visual>
    <origin xyz="0.0 -0.289485 -0.596394" rpy="0 0 0"/>
    <geometry>
      <mesh filename="package://robot_arm_description/meshes/link_5_1.stl" scale="0.001 0.001 0.001"/>
    </geometry>
    <material name="silver"/>
  </visual>
  <collision>
    <origin xyz="0.0 -0.289485 -0.596394" rpy="0 0 0"/>
    <geometry>
      <mesh filename="package://robot_arm_description/meshes/link_5_1.stl" scale="0.001 0.001 0.001"/>
    </geometry>
  </collision>
</link>

<link name="link_6_1">
  <inertial>
    <origin xyz="-0.0006916944165798809 0.03632808398557291 -0.0013926003723436775" rpy="0 0 0"/>
    <mass value="2.637875841155386"/>
    <inertia ixx="0.004764" iyy="0.001978" izz="0.004912" ixy="4.3e-05" iyz="8.7e-05" ixz="6.9e-05"/>
  </inertial>
  <visual>
    <origin xyz="0.002859 -0.314485 -0.596394" rpy="0 0 0"/>
    <geometry>
      <mesh filename="package://robot_arm_description/meshes/link_6_1.stl" scale="0.001 0.001 0.001"/>
    </geometry>
    <material name="silver"/>
  </visual>
  <collision>
    <origin xyz="0.002859 -0.314485 -0.596394" rpy="0 0 0"/>
    <geometry>
      <mesh filename="package://robot_arm_description/meshes/link_6_1.stl" scale="0.001 0.001 0.001"/>
    </geometry>
  </collision>
</link>


<joint name="joint_1" type="revolute">
  <origin xyz="0 0 0.117341" rpy="0 0 0"/>
  <parent link="base_link"/>
  <child link="link_1_1"/>
  <axis xyz="-0.0 -0.0 1.0"/>
  <limit upper="2.443461" lower="-2.443461" effort="100" velocity="100"/>
</joint>

<joint name="joint_2" type="revolute">
  <origin xyz="0 0.0 0.082" rpy="0 0 0"/>
  <parent link="link_1_1"/>
  <child link="link_2_1"/>
  <axis xyz="-1.0 -0.0 -0.0"/>
  <limit upper="2.443461" lower="-2.443461" effort="100" velocity="100"/>
</joint>

<joint name="joint_3" type="revolute">
  <origin xyz="0.0 0 0.299166" rpy="0 0 0"/>
  <parent link="link_2_1"/>
  <child link="link_3_1"/>
  <axis xyz="1.0 0.0 0.0"/>
  <limit upper="2.443461" lower="-2.443461" effort="100" velocity="100"/>
</joint>

<joint name="joint_4" type="revolute">
  <origin xyz="0 0.0 0.097887" rpy="0 0 0"/>
  <parent link="link_3_1"/>
  <child link="link_4_1"/>
  <axis xyz="-0.0 1.0 -0.0"/>
  <limit upper="2.443461" lower="-2.443461" effort="100" velocity="100"/>
</joint>

<joint name="joint_5" type="revolute">
  <origin xyz="0.0 0.2895 0.0" rpy="0 0 0"/>
  <parent link="link_4_1"/>
  <child link="link_5_1"/>
  <axis xyz="1.0 0.0 0.0"/>
  <limit upper="2.443461" lower="-2.443461" effort="100" velocity="100"/>
</joint>

<joint name="joint_6" type="revolute">
  <origin xyz="0.0 0.025 0.0" rpy="0 0 0"/>
  <parent link="link_5_1"/>
  <child link="link_6_1"/>
  <axis xyz="-0.0 1.0 0.0"/>
  <limit upper="2.443461" lower="-2.443461" effort="100" velocity="100"/>
</joint>

</robot>
