<?xml version="1.0" ?>
<!-- =================================================================================== -->
<!-- |    This document was autogenerated by xacro from /home/maven/maven_ws/src/robot_arm_description/urdf/urdf_assembly.xacro | -->
<!-- |    EDITING THIS FILE BY HAND IS NOT RECOMMENDED                                 | -->
<!-- =================================================================================== -->
<robot name="robot_arm">
    
    <link name="base_link">
        
        <visual>
            <origin rpy="0 0 0" xyz="0 0 0" />
            <geometry>
                 <cylinder length="0.11" radius="0.25"/>
            </geometry>
            <material name="silver" />
        </visual>
    </link>
    <link name="link_1_1">
        <inertial>
            <origin rpy="0 0 0" xyz="0 0 0.024001498636141927" />
            <mass value="2.030739431813925" />
            <inertia ixx="0.014477" ixy="-0.000145" ixz="1.6e-05" iyy="0.006803" iyz="0.000726" izz="0.0131" />
        </inertial>
        <visual>
            <origin rpy="0 0 0" xyz="0 0 -0.117341" />
            <geometry>
                <mesh filename="package://robot_arm_description/meshes/link_1_1.stl" scale="0.001 0.001 0.001" />
            </geometry>
            <material name="silver" />
        </visual>
        <collision>
            <origin rpy="0 0 0" xyz="0 0 -0.117341" />
            <geometry>
                <mesh filename="package://robot_arm_description/meshes/link_1_1.stl" scale="0.001 0.001 0.001" />
            </geometry>
        </collision>
    </link>
    <link name="link_2_1">
        <inertial>
            <origin rpy="0 0 0" xyz="0 0 0.13687546860146899" />
            <mass value="1.6626610036452254" />
            <inertia ixx="0.024251" ixy="0.0" ixz="-2.6e-05" iyy="0.026584" iyz="7e-06" izz="0.005086" />
        </inertial>
        <visual>
            <origin rpy="0 0 0" xyz="0 0.002 -0.199341" />
            <geometry>
                <mesh filename="package://robot_arm_description/meshes/link_2_1.stl" scale="0.001 0.001 0.001" />
            </geometry>
            <material name="silver" />
        </visual>
        <collision>
            <origin rpy="0 0 0" xyz="0 0 -0.199341" />
            <geometry>
                <mesh filename="package://robot_arm_description/meshes/link_2_1.stl" scale="0.001 0.001 0.001" />
            </geometry>
        </collision>
    </link>
    <link name="link_3_1">
        <inertial>
            <origin rpy="0 0 0" xyz="0 -0.016283006892585307 0.07497937866412202" />
            <mass value="9.121346283290384" />
            <inertia ixx="0.063998" ixy="2.5e-05" ixz="-0.000107" iyy="0.062586" iyz="0.007821" izz="0.038355" />
        </inertial>
        <visual>
            <origin rpy="0 0 0" xyz="0 0.002793 -0.498507" />
            <geometry>
                <mesh filename="package://robot_arm_description/meshes/link_3_1.stl" scale="0.001 0.001 0.001" />
            </geometry>
            <material name="silver" />
        </visual>
        <collision>
            <origin rpy="0 0 0" xyz="0 0.002793 -0.498507" />
            <geometry>
                <mesh filename="package://robot_arm_description/meshes/link_3_1.stl" scale="0.001 0.001 0.001" />
            </geometry>
        </collision>
    </link>
    <link name="link_4_1">
        <inertial>
            <origin rpy="0 0 0" xyz="0.005513953778460314 0.2625680653929481 4.057984306360396e-06" />
            <mass value="7.5787166188185005" />
            <inertia ixx="0.126085" ixy="-0.000913" ixz="-2e-06" iyy="0.027107" iyz="-1e-06" izz="0.147683" />
        </inertial>
        <visual>
            <origin rpy="0 0 0" xyz="0.002859 0.112793 -0.596394" />
            <geometry>
                <mesh filename="package://robot_arm_description/meshes/link_4_1.stl" scale="0.001 0.001 0.001" />
            </geometry>
            <material name="silver" />
        </visual>
        <collision>
            <origin rpy="0 0 0" xyz="0.002859 0.112793 -0.596394" />
            <geometry>
                <mesh filename="package://robot_arm_description/meshes/link_4_1.stl" scale="0.001 0.001 0.001" />
            </geometry>
        </collision>
    </link>
    <link name="link_5_1">
        <inertial>
            <origin rpy="0 0 0" xyz="-0.07848672877351807 -0.01878037329851351 1.0025048180262175e-05" />
            <mass value="3.0872435381050845" />
            <inertia ixx="0.004619" ixy="-0.001102" ixz="0.0" iyy="0.008205" iyz="2e-06" izz="0.009933" />
        </inertial>
        <visual>
            <origin rpy="0 0 0" xyz="-0.094641 -0.289485 -0.596394" />
            <geometry>
                <mesh filename="package://robot_arm_description/meshes/link_5_1.stl" scale="0.001 0.001 0.001" />
            </geometry>
            <material name="silver" />
        </visual>
        <collision>
            <origin rpy="0 0 0" xyz="-0.094641 -0.289485 -0.596394" />
            <geometry>
                <mesh filename="package://robot_arm_description/meshes/link_5_1.stl" scale="0.001 0.001 0.001" />
            </geometry>
        </collision>
    </link>
    <link name="link_6_1">
        <inertial>
            <origin rpy="0 0 0" xyz="-0.0006916944165798809 0.03632808398557291 -0.0013926003723436775" />
            <mass value="2.637875841155386" />
            <inertia ixx="0.004764" ixy="4.3e-05" ixz="6.9e-05" iyy="0.001978" iyz="8.7e-05" izz="0.004912" />
        </inertial>
        <visual>
            <origin rpy="0 0 0" xyz="0.002859 -0.314485 -0.596394" />
            <geometry>
                <mesh filename="package://robot_arm_description/meshes/link_6_1.stl" scale="0.001 0.001 0.001" />
            </geometry>
            <material name="silver" />
        </visual>
        <collision>
            <origin rpy="0 0 0" xyz="0.002859 -0.314485 -0.596394" />
            <geometry>
                <mesh filename="package://robot_arm_description/meshes/link_6_1.stl" scale="0.001 0.001 0.001" />
            </geometry>
        </collision>
    </link>
    <link name="link_7_1">
        <inertial>
            <origin rpy="0 0 0" xyz="0.005289159325895416 0.05604353410292273 -0.03427022222823228" />
            <mass value="0.8308399781572773" />
            <inertia ixx="0.001677" ixy="5e-05" ixz="1e-06" iyy="0.000955" iyz="3e-06" izz="0.000833" />
        </inertial>
        <visual>
            <origin rpy="0 0 0" xyz="-0.01211 -0.374485 -0.630669" />
            <geometry>
                <mesh filename="package://robot_arm_description/meshes/link_7_1.stl" scale="0.001 0.001 0.001" />
            </geometry>
            <material name="silver" />
        </visual>
        <collision>
            <origin rpy="0 0 0" xyz="-0.01211 -0.374485 -0.630669" />
            <geometry>
                <mesh filename="package://robot_arm_description/meshes/link_7_1.stl" scale="0.001 0.001 0.001" />
            </geometry>
        </collision>
    </link>
    <link name="link_8_1">
        <inertial>
            <origin rpy="0 0 0" xyz="-0.0054920854200500475 0.05617084434859132 -0.03817503247390952" />
            <mass value="0.8293395046016687" />
            <inertia ixx="0.001672" ixy="-4.8e-05" ixz="-1e-06" iyy="0.000956" iyz="-0.0" izz="0.000827" />
        </inertial>
        <visual>
            <origin rpy="0 0 0" xyz="0.01809 -0.374485 -0.634569" />
            <geometry>
                <mesh filename="package://robot_arm_description/meshes/link_8_1.stl" scale="0.001 0.001 0.001" />
            </geometry>
            <material name="silver" />
        </visual>
        <collision>
            <origin rpy="0 0 0" xyz="0.01809 -0.374485 -0.634569" />
            <geometry>
                <mesh filename="package://robot_arm_description/meshes/link_8_1.stl" scale="0.001 0.001 0.001" />
            </geometry>
        </collision>
    </link>

    <joint name="joint_1" type="revolute">
        <origin rpy="0 0 0" xyz="0 0 0.117341" />
        <parent link="base_link" />
        <child link="link_1_1" />
        <axis xyz="-0.0 -0.0 1.0" />
    </joint>
    <joint name="joint_2" type="revolute">
        <origin rpy="0 0 0" xyz="0 0.0 0.082" />
        <parent link="link_1_1" />
        <child link="link_2_1" />
        <axis xyz="-1.0 -0.0 -0.0" />
        <limit effort="100" lower="-0.872665" upper="1.570796" velocity="100" />
    </joint>
    <joint name="joint_3" type="revolute">
        <origin rpy="0 0 0" xyz="0.0 0 0.299166" />
        <parent link="link_2_1" />
        <child link="link_3_1" />
        <axis xyz="1.0 0.0 0.0" />
        <limit effort="100" lower="-1.570796" upper="1.570796" velocity="100" />
    </joint>
    <joint name="joint_4" type="revolute">
        <origin rpy="0 0 0" xyz="0 -0.11 0.097887" />
        <parent link="link_3_1" />
        <child link="link_4_1" />
        <axis xyz="-0.0 1.0 -0.0" />
    </joint>
    <joint name="joint_5" type="revolute">
        <origin rpy="0 0 0" xyz="0.0975 0.402278 0.0" />
        <parent link="link_4_1" />
        <child link="link_5_1" />
        <axis xyz="1.0 0.0 0.0" />
        <limit effort="100" lower="-2.443461" upper="2.443461" velocity="100" />
    </joint>
    <joint name="joint_6" type="revolute">
        <origin rpy="0 0 0" xyz="-0.0975 0.025 0.0" />
        <parent link="link_5_1" />
        <child link="link_6_1" />
        <axis xyz="-0.0 1.0 0.0" />
    </joint>
    <joint name="joint_7" type="revolute">
        <origin rpy="0 0 0" xyz="0.014969 0.06 0.034275" />
        <parent link="link_6_1" />
        <child link="link_7_1" />
        <axis xyz="-0.0 -0.0 1.0" />
        <limit effort="100" lower="-1.570796" upper="0.0" velocity="100" />
    </joint>
    <joint name="joint_8" type="revolute">
        <origin rpy="0 0 0" xyz="-0.015231 0.06 0.038175" />
        <parent link="link_6_1" />
        <child link="link_8_1" />
        <axis xyz="-0.0 -0.0 1.0" />
        <limit effort="100" lower="0.0" upper="1.570796" velocity="100" />
    </joint>
</robot>

